Traceback (most recent call last):
  File "/opt/hostedtoolcache/Python/3.13.1/x64/lib/python3.13/site-packages/jupyter_cache/executors/utils.py", line 58, in single_nb_execution
    executenb(
    ~~~~~~~~~^
        nb,
        ^^^
    ...<4 lines>...
        **kwargs,
        ^^^^^^^^^
    )
    ^
  File "/opt/hostedtoolcache/Python/3.13.1/x64/lib/python3.13/site-packages/nbclient/client.py", line 1319, in execute
    return NotebookClient(nb=nb, resources=resources, km=km, **kwargs).execute()
           ~~~~~~~~~~~~~~~~~~~~~~~~~~~~~~~~~~~~~~~~~~~~~~~~~~~~~~~~~~~~~~~~~~~^^
  File "/opt/hostedtoolcache/Python/3.13.1/x64/lib/python3.13/site-packages/jupyter_core/utils/__init__.py", line 165, in wrapped
    return loop.run_until_complete(inner)
           ~~~~~~~~~~~~~~~~~~~~~~~^^^^^^^
  File "/opt/hostedtoolcache/Python/3.13.1/x64/lib/python3.13/asyncio/base_events.py", line 720, in run_until_complete
    return future.result()
           ~~~~~~~~~~~~~^^
  File "/opt/hostedtoolcache/Python/3.13.1/x64/lib/python3.13/site-packages/nbclient/client.py", line 709, in async_execute
    await self.async_execute_cell(
        cell, index, execution_count=self.code_cells_executed + 1
    )
  File "/opt/hostedtoolcache/Python/3.13.1/x64/lib/python3.13/site-packages/nbclient/client.py", line 1062, in async_execute_cell
    await self._check_raise_for_error(cell, cell_index, exec_reply)
  File "/opt/hostedtoolcache/Python/3.13.1/x64/lib/python3.13/site-packages/nbclient/client.py", line 918, in _check_raise_for_error
    raise CellExecutionError.from_cell_and_msg(cell, exec_reply_content)
nbclient.exceptions.CellExecutionError: An error occurred while executing the following cell:
------------------
import os
procs = os.cpu_count()
print("No. of processors =", os.cpu_count())

def modify(sample):
    sample['num_word'] = len(sample['text'].split())
    return sample
ds = ds.map(modify, batch_size=7000, num_proc=procs, disable_progress_bar=True)    
print(ds)
------------------

----- stdout -----
No. of processors = 4
------------------

[0;31m---------------------------------------------------------------------------[0m
[0;31mNameError[0m                                 Traceback (most recent call last)
Cell [0;32mIn[2], line 8[0m
[1;32m      6[0m     sample[[38;5;124m'[39m[38;5;124mnum_word[39m[38;5;124m'[39m] [38;5;241m=[39m [38;5;28mlen[39m(sample[[38;5;124m'[39m[38;5;124mtext[39m[38;5;124m'[39m][38;5;241m.[39msplit())
[1;32m      7[0m     [38;5;28;01mreturn[39;00m sample
[0;32m----> 8[0m ds [38;5;241m=[39m [43mds[49m[38;5;241m.[39mmap(modify, batch_size[38;5;241m=[39m[38;5;241m7000[39m, num_proc[38;5;241m=[39mprocs, disable_progress_bar[38;5;241m=[39m[38;5;28;01mTrue[39;00m)    
[1;32m      9[0m [38;5;28mprint[39m(ds)

[0;31mNameError[0m: name 'ds' is not defined

